Workbook

Sheet Premissas
A1: Tamanho do cartão | B1: Minutos | C1: Horas
A2: PP | B2: 15 | C2: =B2/60 -> 0.25
A3: P | B3: 30 | C3: =B3/60 -> 0.5
A4: M | B4: 60 | C4: =B4/60 -> 1
A5: G | B5: 120 | C5: =B5/60 -> 2
A6: GG | B6: 240 | C6: =B6/60 -> 4
A8: Regras de classificação
A9: Esforço = tempo do cartão somado toda vez que ele entra em uma das 4 etapas do Kanban (Backlog, Doing, Waiting Review, Review).
A10: Atividade = movimentações Kanban + commits + MRs abertas + MRs aprovadas.
A11: [externo] e [bot] ficam fora dos indicadores por aluno (aparecem na base).
A12: Sprint definida pela data de início:
A13: Sprint 01 | B13: 2026-04-22
A14: Sprint 02 | B14: 2026-05-04
A15: Sprint 03 | B15: 2026-05-18
A16: Sprint 04 | B16: 2026-06-01
A17: Sprint 05 | B17: 2026-06-15

Sheet Aluno (total)
A1: Aluno | B1: Grupo | C1: Cartões | D1: Commits | E1: MRs (abertas + aprovadas) | F1: Movimentações Kanban | G1: Esforço (h) | H1: Atividades totais
A2: G01-A12 | B2: G01 | C2: =SUMIFS('Aluno x Sprint'!$D$2:$D$121,'Aluno x Sprint'!$A$2:$A$121,$A2) -> 52 | D2: =SUMIFS('Aluno x Sprint'!$E$2:$E$121,'Aluno x Sprint'!$A$2:$A$121,$A2) -> 69 | E2: =SUMIFS('Aluno x Sprint'!$H$2:$H$121,'Aluno x Sprint'!$A$2:$A$121,$A2) -> 27 | F2: =SUMIFS('Aluno x Sprint'!$I$2:$I$121,'Aluno x Sprint'!$A$2:$A$121,$A2) -> 459 | G2: =SUMIFS('Aluno x Sprint'!$K$2:$K$121,'Aluno x Sprint'!$A$2:$A$121,$A2) -> 358.25 | H2: =SUMIFS('Aluno x Sprint'!$L$2:$L$121,'Aluno x Sprint'!$A$2:$A$121,$A2) -> 555
A3: G01-A13 | B3: G01 | C3: =SUMIFS('Aluno x Sprint'!$D$2:$D$121,'Aluno x Sprint'!$A$2:$A$121,$A3) -> 22 | D3: =SUMIFS('Aluno x Sprint'!$E$2:$E$121,'Aluno x Sprint'!$A$2:$A$121,$A3) -> 41 | E3: =SUMIFS('Aluno x Sprint'!$H$2:$H$121,'Aluno x Sprint'!$A$2:$A$121,$A3) -> 22 | F3: =SUMIFS('Aluno x Sprint'!$I$2:$I$121,'Aluno x Sprint'!$A$2:$A$121,$A3) -> 162 | G3: =SUMIFS('Aluno x Sprint'!$K$2:$K$121,'Aluno x Sprint'!$A$2:$A$121,$A3) -> 162.25 | H3: =SUMIFS('Aluno x Sprint'!$L$2:$L$121,'Aluno x Sprint'!$A$2:$A$121,$A3) -> 225
A4: G01-A14 | B4: G01 | C4: =SUMIFS('Aluno x Sprint'!$D$2:$D$121,'Aluno x Sprint'!$A$2:$A$121,$A4) -> 50 | D4: =SUMIFS('Aluno x Sprint'!$E$2:$E$121,'Aluno x Sprint'!$A$2:$A$121,$A4) -> 128 | E4: =SUMIFS('Aluno x Sprint'!$H$2:$H$121,'Aluno x Sprint'!$A$2:$A$121,$A4) -> 95 | F4: =SUMIFS('Aluno x Sprint'!$I$2:$I$121,'Aluno x Sprint'!$A$2:$A$121,$A4) -> 374 | G4: =SUMIFS('Aluno x Sprint'!$K$2:$K$121,'Aluno x Sprint'!$A$2:$A$121,$A4) -> 332.25 | H4: =SUMIFS('Aluno x Sprint'!$L$2:$L$121,'Aluno x Sprint'!$A$2:$A$121,$A4) -> 597
A5: G01-A15 | B5: G01 | C5: =SUMIFS('Aluno x Sprint'!$D$2:$D$121,'Aluno x Sprint'!$A$2:$A$121,$A5) -> 50 | D5: =SUMIFS('Aluno x Sprint'!$E$2:$E$121,'Aluno x Sprint'!$A$2:$A$121,$A5) -> 76 | E5: =SUMIFS('Aluno x Sprint'!$H$2:$H$121,'Aluno x Sprint'!$A$2:$A$121,$A5) -> 48 | F5: =SUMIFS('Aluno x Sprint'!$I$2:$I$121,'Aluno x Sprint'!$A$2:$A$121,$A5) -> 626 | G5: =SUMIFS('Aluno x Sprint'!$K$2:$K$121,'Aluno x Sprint'!$A$2:$A$121,$A5) -> 609.25 | H5: =SUMIFS('Aluno x Sprint'!$L$2:$L$121,'Aluno x Sprint'!$A$2:$A$121,$A5) -> 750
A6: G01-A16 | B6: G01 | C6: =SUMIFS('Aluno x Sprint'!$D$2:$D$121,'Aluno x Sprint'!$A$2:$A$121,$A6) -> 26 | D6: =SUMIFS('Aluno x Sprint'!$E$2:$E$121,'Aluno x Sprint'!$A$2:$A$121,$A6) -> 4 | E6: =SUMIFS('Aluno x Sprint'!$H$2:$H$121,'Aluno x Sprint'!$A$2:$A$121,$A6) -> 15 | F6: =SUMIFS('Aluno x Sprint'!$I$2:$I$121,'Aluno x Sprint'!$A$2:$A$121,$A6) -> 197 | G6: =SUMIFS('Aluno x Sprint'!$K$2:$K$121,'Aluno x Sprint'!$A$2:$A$121,$A6) -> 170.75 | H6: =SUMIFS('Aluno x Sprint'!$L$2:$L$121,'Aluno x Sprint'!$A$2:$A$121,$A6) -> 216
A7: G01-A17 | B7: G01 | C7: =SUMIFS('Aluno x Sprint'!$D$2:$D$121,'Aluno x Sprint'!$A$2:$A$121,$A7) -> 47 | D7: =SUMIFS('Aluno x Sprint'!$E$2:$E$121,'Aluno x Sprint'!$A$2:$A$121,$A7) -> 127 | E7: =SUMIFS('Aluno x Sprint'!$H$2:$H$121,'Aluno x Sprint'!$A$2:$A$121,$A7) -> 55 | F7: =SUMIFS('Aluno x Sprint'!$I$2:$I$121,'Aluno x Sprint'!$A$2:$A$121,$A7) -> 320 | G7: =SUMIFS('Aluno x Sprint'!$K$2:$K$121,'Aluno x Sprint'!$A$2:$A$121,$A7) -> 385.75 | H7: =SUMIFS('Aluno x Sprint'!$L$2:$L$121,'Aluno x Sprint'!$A$2:$A$121,$A7) -> 502
A8: G01-A23 | B8: G01 | C8: =SUMIFS('Aluno x Sprint'!$D$2:$D$121,'Aluno x Sprint'!$A$2:$A$121,$A8) -> 16 | D8: =SUMIFS('Aluno x Sprint'!$E$2:$E$121,'Aluno x Sprint'!$A$2:$A$121,$A8) -> 15 | E8: =SUMIFS('Aluno x Sprint'!$H$2:$H$121,'Aluno x Sprint'!$A$2:$A$121,$A8) -> 12 | F8: =SUMIFS('Aluno x Sprint'!$I$2:$I$121,'Aluno x Sprint'!$A$2:$A$121,$A8) -> 65 | G8: =SUMIFS('Aluno x Sprint'!$K$2:$K$121,'Aluno x Sprint'!$A$2:$A$121,$A8) -> 41 | H8: =SUMIFS('Aluno x Sprint'!$L$2:$L$121,'Aluno x Sprint'!$A$2:$A$121,$A8) -> 92
A9: G02-A12 | B9: G02 | C9: =SUMIFS('Aluno x Sprint'!$D$2:$D$121,'Aluno x Sprint'!$A$2:$A$121,$A9) -> 119 | D9: =SUMIFS('Aluno x Sprint'!$E$2:$E$121,'Aluno x Sprint'!$A$2:$A$121,$A9) -> 167 | E9: =SUMIFS('Aluno x Sprint'!$H$2:$H$121,'Aluno x Sprint'!$A$2:$A$121,$A9) -> 82 | F9: =SUMIFS('Aluno x Sprint'!$I$2:$I$121,'Aluno x Sprint'!$A$2:$A$121,$A9) -> 1029 | G9: =SUMIFS('Aluno x Sprint'!$K$2:$K$121,'Aluno x Sprint'!$A$2:$A$121,$A9) -> 913.5 | H9: =SUMIFS('Aluno x Sprint'!$L$2:$L$121,'Aluno x Sprint'!$A$2:$A$121,$A9) -> 1278
A10: G02-A13 | B10: G02 | C10: =SUMIFS('Aluno x Sprint'!$D$2:$D$121,'Aluno x Sprint'!$A$2:$A$121,$A10) -> 40 | D10: =SUMIFS('Aluno x Sprint'!$E$2:$E$121,'Aluno x Sprint'!$A$2:$A$121,$A10) -> 57 | E10: =SUMIFS('Aluno x Sprint'!$H$2:$H$121,'Aluno x Sprint'!$A$2:$A$121,$A10) -> 30 | F10: =SUMIFS('Aluno x Sprint'!$I$2:$I$121,'Aluno x Sprint'!$A$2:$A$121,$A10) -> 319 | G10: =SUMIFS('Aluno x Sprint'!$K$2:$K$121,'Aluno x Sprint'!$A$2:$A$121,$A10) -> 421 | H10: =SUMIFS('Aluno x Sprint'!$L$2:$L$121,'Aluno x Sprint'!$A$2:$A$121,$A10) -> 406
A11: G02-A14 | B11: G02 | C11: =SUMIFS('Aluno x Sprint'!$D$2:$D$121,'Aluno x Sprint'!$A$2:$A$121,$A11) -> 28 | D11: =SUMIFS('Aluno x Sprint'!$E$2:$E$121,'Aluno x Sprint'!$A$2:$A$121,$A11) -> 113 | E11: =SUMIFS('Aluno x Sprint'!$H$2:$H$121,'Aluno x Sprint'!$A$2:$A$121,$A11) -> 47 | F11: =SUMIFS('Aluno x Sprint'!$I$2:$I$121,'Aluno x Sprint'!$A$2:$A$121,$A11) -> 226 | G11: =SUMIFS('Aluno x Sprint'!$K$2:$K$121,'Aluno x Sprint'!$A$2:$A$121,$A11) -> 359.5 | H11: =SUMIFS('Aluno x Sprint'!$L$2:$L$121,'Aluno x Sprint'!$A$2:$A$121,$A11) -> 386
A12: G02-A15 | B12: G02 | C12: =SUMIFS('Aluno x Sprint'!$D$2:$D$121,'Aluno x Sprint'!$A$2:$A$121,$A12) -> 68 | D12: =SUMIFS('Aluno x Sprint'!$E$2:$E$121,'Aluno x Sprint'!$A$2:$A$121,$A12) -> 261 | E12: =SUMIFS('Aluno x Sprint'!$H$2:$H$121,'Aluno x Sprint'!$A$2:$A$121,$A12) -> 102 | F12: =SUMIFS('Aluno x Sprint'!$I$2:$I$121,'Aluno x Sprint'!$A$2:$A$121,$A12) -> 555 | G12: =SUMIFS('Aluno x Sprint'!$K$2:$K$121,'Aluno x Sprint'!$A$2:$A$121,$A12) -> 522.25 | H12: =SUMIFS('Aluno x Sprint'!$L$2:$L$121,'Aluno x Sprint'!$A$2:$A$121,$A12) -> 918
A13: G02-A16 | B13: G02 | C13: =SUMIFS('Aluno x Sprint'!$D$2:$D$121,'Aluno x Sprint'!$A$2:$A$121,$A13) -> 58 | D13: =SUMIFS('Aluno x Sprint'!$E$2:$E$121,'Aluno x Sprint'!$A$2:$A$121,$A13) -> 101 | E13: =SUMIFS('Aluno x Sprint'!$H$2:$H$121,'Aluno x Sprint'!$A$2:$A$121,$A13) -> 29 | F13: =SUMIFS('Aluno x Sprint'!$I$2:$I$121,'Aluno x Sprint'!$A$2:$A$121,$A13) -> 438 | G13: =SUMIFS('Aluno x Sprint'!$K$2:$K$121,'Aluno x Sprint'!$A$2:$A$121,$A13) -> 490.5 | H13: =SUMIFS('Aluno x Sprint'!$L$2:$L$121,'Aluno x Sprint'!$A$2:$A$121,$A13) -> 568
... A25: G03-A19 | B25: G03 | C25: =SUMIFS('Aluno x Sprint'!$D$2:$D$121,'Aluno x Sprint'!$A$2:$A$121,$A25) -> 24 | D25: =SUMIFS('Aluno x Sprint'!$E$2:$E$121,'Aluno x Sprint'!$A$2:$A$121,$A25) -> 58 | E25: =SUMIFS('Aluno x Sprint'!$H$2:$H$121,'Aluno x Sprint'!$A$2:$A$121,$A25) -> 19 | F25: =SUMIFS('Aluno x Sprint'!$I$2:$I$121,'Aluno x Sprint'!$A$2:$A$121,$A25) -> 244 | G25: =SUMIFS('Aluno x Sprint'!$K$2:$K$121,'Aluno x Sprint'!$A$2:$A$121,$A25) -> 164.25 | H25: =SUMIFS('Aluno x Sprint'!$L$2:$L$121,'Aluno x Sprint'!$A$2:$A$121,$A25) -> 321

Sheet Aluno x Sprint
A1: Aluno | B1: Grupo | C1: Sprint | D1: Cartões | E1: Commits | F1: MRs abertas | G1: MRs aprovadas | H1: MRs (abertas + aprovadas) | I1: Movimentações Kanban | J1: Esforço (min) | K1: Esforço (h) | L1: Atividades totais
A2: G01-A12 | B2: G01 | C2: Sprint 01 | D2: 9 | E2: =SUMIFS(Base!$F$2:$F$2938,Base!$A$2:$A$2938,$A2,Base!$D$2:$D$2938,$C2,Base!$E$2:$E$2938,"Commit") -> 14 | F2: =SUMIFS(Base!$F$2:$F$2938,Base!$A$2:$A$2938,$A2,Base!$D$2:$D$2938,$C2,Base!$E$2:$E$2938,"MR aberta") -> 4 | G2: =SUMIFS(Base!$F$2:$F$2938,Base!$A$2:$A$2938,$A2,Base!$D$2:$D$2938,$C2,Base!$E$2:$E$2938,"MR aprovada") -> 6 | H2: =F2+G2 -> 10 | I2: =SUMIFS(Base!$F$2:$F$2938,Base!$A$2:$A$2938,$A2,Base!$D$2:$D$2938,$C2,Base!$E$2:$E$2938,"Backlog")+SUMIFS(Base!$F$2:$F$2938,Base!$A$2:$A$2938,$A2,Base!$D$2:$D$2938,$C2,Base!$E$2:$E$2938,"Doing")+SUMIFS(Base!$F$2:$F$2938,Base!$A$2:$A$2938,$A2,Base!$D$2:$D$2938,$C2,Base!$E$2:$E$2938,"Waiting Review")+SUMIFS(Base!$F$2:$F$2938,Base!$A$2:$A$2938,$A2,Base!$D$2:$D$2938,$C2,Base!$E$2:$E$2938,"Review") -> 80 | J2: =SUMIFS(Base!$G$2:$G$2938,Base!$A$2:$A$2938,$A2,Base!$D$2:$D$2938,$C2) -> 5250 | K2: =J2/60 -> 87.5 | L2: =E2+F2+G2+I2 -> 104
A3: G01-A12 | B3: G01 | C3: Sprint 02 | D3: 9 | E3: =SUMIFS(Base!$F$2:$F$2938,Base!$A$2:$A$2938,$A3,Base!$D$2:$D$2938,$C3,Base!$E$2:$E$2938,"Commit") -> 4 | F3: =SUMIFS(Base!$F$2:$F$2938,Base!$A$2:$A$2938,$A3,Base!$D$2:$D$2938,$C3,Base!$E$2:$E$2938,"MR aberta") -> 0 | G3: =SUMIFS(Base!$F$2:$F$2938,Base!$A$2:$A$2938,$A3,Base!$D$2:$D$2938,$C3,Base!$E$2:$E$2938,"MR aprovada") -> 1 | H3: =F3+G3 -> 1 | I3: =SUMIFS(Base!$F$2:$F$2938,Base!$A$2:$A$2938,$A3,Base!$D$2:$D$2938,$C3,Base!$E$2:$E$2938,"Backlog")+SUMIFS(Base!$F$2:$F$2938,Base!$A$2:$A$2938,$A3,Base!$D$2:$D$2938,$C3,Base!$E$2:$E$2938,"Doing")+SUMIFS(Base!$F$2:$F$2938,Base!$A$2:$A$2938,$A3,Base!$D$2:$D$2938,$C3,Base!$E$2:$E$2938,"Waiting Review")+SUMIFS(Base!$F$2:$F$2938,Base!$A$2:$A$2938,$A3,Base!$D$2:$D$2938,$C3,Base!$E$2:$E$2938,"Review") -> 53 | J3: =SUMIFS(Base!$G$2:$G$2938,Base!$A$2:$A$2938,$A3,Base!$D$2:$D$2938,$C3) -> 1335 | K3: =J3/60 -> 22.25 | L3: =E3+F3+G3+I3 -> 58
A4: G01-A12 | B4: G01 | C4: Sprint 03 | D4: 18 | E4: =SUMIFS(Base!$F$2:$F$2938,Base!$A$2:$A$2938,$A4,Base!$D$2:$D$2938,$C4,Base!$E$2:$E$2938,"Commit") -> 25 | F4: =SUMIFS(Base!$F$2:$F$2938,Base!$A$2:$A$2938,$A4,Base!$D$2:$D$2938,$C4,Base!$E$2:$E$2938,"MR aberta") -> 3 | G4: =SUMIFS(Base!$F$2:$F$2938,Base!$A$2:$A$2938,$A4,Base!$D$2:$D$2938,$C4,Base!$E$2:$E$2938,"MR aprovada") -> 4 | H4: =F4+G4 -> 7 | I4: =SUMIFS(Base!$F$2:$F$2938,Base!$A$2:$A$2938,$A4,Base!$D$2:$D$2938,$C4,Base!$E$2:$E$2938,"Backlog")+SUMIFS(Base!$F$2:$F$2938,Base!$A$2:$A$2938,$A4,Base!$D$2:$D$2938,$C4,Base!$E$2:$E$2938,"Doing")+SUMIFS(Base!$F$2:$F$2938,Base!$A$2:$A$2938,$A4,Base!$D$2:$D$2938,$C4,Base!$E$2:$E$2938,"Waiting Review")+SUMIFS(Base!$F$2:$F$2938,Base!$A$2:$A$2938,$A4,Base!$D$2:$D$2938,$C4,Base!$E$2:$E$2938,"Review") -> 93 | J4: =SUMIFS(Base!$G$2:$G$2938,Base!$A$2:$A$2938,$A4,Base!$D$2:$D$2938,$C4) -> 7020 | K4: =J4/60 -> 117 | L4: =E4+F4+G4+I4 -> 125
A5: G01-A12 | B5: G01 | C5: Sprint 04 | D5: 6 | E5: =SUMIFS(Base!$F$2:$F$2938,Base!$A$2:$A$2938,$A5,Base!$D$2:$D$2938,$C5,Base!$E$2:$E$2938,"Commit") -> 8 | F5: =SUMIFS(Base!$F$2:$F$2938,Base!$A$2:$A$2938,$A5,Base!$D$2:$D$2938,$C5,Base!$E$2:$E$2938,"MR aberta") -> 2 | G5: =SUMIFS(Base!$F$2:$F$2938,Base!$A$2:$A$2938,$A5,Base!$D$2:$D$2938,$C5,Base!$E$2:$E$2938,"MR aprovada") -> 0 | H5: =F5+G5 -> 2 | I5: =SUMIFS(Base!$F$2:$F$2938,Base!$A$2:$A$2938,$A5,Base!$D$2:$D$2938,$C5,Base!$E$2:$E$2938,"Backlog")+SUMIFS(Base!$F$2:$F$2938,Base!$A$2:$A$2938,$A5,Base!$D$2:$D$2938,$C5,Base!$E$2:$E$2938,"Doing")+SUMIFS(Base!$F$2:$F$2938,Base!$A$2:$A$2938,$A5,Base!$D$2:$D$2938,$C5,Base!$E$2:$E$2938,"Waiting Review")+SUMIFS(Base!$F$2:$F$2938,Base!$A$2:$A$2938,$A5,Base!$D$2:$D$2938,$C5,Base!$E$2:$E$2938,"Review") -> 169 | J5: =SUMIFS(Base!$G$2:$G$2938,Base!$A$2:$A$2938,$A5,Base!$D$2:$D$2938,$C5) -> 5985 | K5: =J5/60 -> 99.75 | L5: =E5+F5+G5+I5 -> 179
A6: G01-A12 | B6: G01 | C6: Sprint 05 | D6: 10 | E6: =SUMIFS(Base!$F$2:$F$2938,Base!$A$2:$A$2938,$A6,Base!$D$2:$D$2938,$C6,Base!$E$2:$E$2938,"Commit") -> 18 | F6: =SUMIFS(Base!$F$2:$F$2938,Base!$A$2:$A$2938,$A6,Base!$D$2:$D$2938,$C6,Base!$E$2:$E$2938,"MR aberta") -> 3 | G6: =SUMIFS(Base!$F$2:$F$2938,Base!$A$2:$A$2938,$A6,Base!$D$2:$D$2938,$C6,Base!$E$2:$E$2938,"MR aprovada") -> 4 | H6: =F6+G6 -> 7 | I6: =SUMIFS(Base!$F$2:$F$2938,Base!$A$2:$A$2938,$A6,Base!$D$2:$D$2938,$C6,Base!$E$2:$E$2938,"Backlog")+SUMIFS(Base!$F$2:$F$2938,Base!$A$2:$A$2938,$A6,Base!$D$2:$D$2938,$C6,Base!$E$2:$E$2938,"Doing")+SUMIFS(Base!$F$2:$F$2938,Base!$A$2:$A$2938,$A6,Base!$D$2:$D$2938,$C6,Base!$E$2:$E$2938,"Waiting Review")+SUMIFS(Base!$F$2:$F$2938,Base!$A$2:$A$2938,$A6,Base!$D$2:$D$2938,$C6,Base!$E$2:$E$2938,"Review") -> 64 | J6: =SUMIFS(Base!$G$2:$G$2938,Base!$A$2:$A$2938,$A6,Base!$D$2:$D$2938,$C6) -> 1905 | K6: =J6/60 -> 31.75 | L6: =E6+F6+G6+I6 -> 89
A7: G01-A13 | B7: G01 | C7: Sprint 01 | D7: 3 | E7: =SUMIFS(Base!$F$2:$F$2938,Base!$A$2:$A$2938,$A7,Base!$D$2:$D$2938,$C7,Base!$E$2:$E$2938,"Commit") -> 2 | F7: =SUMIFS(Base!$F$2:$F$2938,Base!$A$2:$A$2938,$A7,Base!$D$2:$D$2938,$C7,Base!$E$2:$E$2938,"MR aberta") -> 1 | G7: =SUMIFS(Base!$F$2:$F$2938,Base!$A$2:$A$2938,$A7,Base!$D$2:$D$2938,$C7,Base!$E$2:$E$2938,"MR aprovada") -> 0 | H7: =F7+G7 -> 1 | I7: =SUMIFS(Base!$F$2:$F$2938,Base!$A$2:$A$2938,$A7,Base!$D$2:$D$2938,$C7,Base!$E$2:$E$2938,"Backlog")+SUMIFS(Base!$F$2:$F$2938,Base!$A$2:$A$2938,$A7,Base!$D$2:$D$2938,$C7,Base!$E$2:$E$2938,"Doing")+SUMIFS(Base!$F$2:$F$2938,Base!$A$2:$A$2938,$A7,Base!$D$2:$D$2938,$C7,Base!$E$2:$E$2938,"Waiting Review")+SUMIFS(Base!$F$2:$F$2938,Base!$A$2:$A$2938,$A7,Base!$D$2:$D$2938,$C7,Base!$E$2:$E$2938,"Review") -> 17 | J7: =SUMIFS(Base!$G$2:$G$2938,Base!$A$2:$A$2938,$A7,Base!$D$2:$D$2938,$C7) -> 1260 | K7: =J7/60 -> 21 | L7: =E7+F7+G7+I7 -> 20
A8: G01-A13 | B8: G01 | C8: Sprint 02 | D8: 4 | E8: =SUMIFS(Base!$F$2:$F$2938,Base!$A$2:$A$2938,$A8,Base!$D$2:$D$2938,$C8,Base!$E$2:$E$2938,"Commit") -> 3 | F8: =SUMIFS(Base!$F$2:$F$2938,Base!$A$2:$A$2938,$A8,Base!$D$2:$D$2938,$C8,Base!$E$2:$E$2938,"MR aberta") -> 1 | G8: =SUMIFS(Base!$F$2:$F$2938,Base!$A$2:$A$2938,$A8,Base!$D$2:$D$2938,$C8,Base!$E$2:$E$2938,"MR aprovada") -> 0 | H8: =F8+G8 -> 1 | I8: =SUMIFS(Base!$F$2:$F$2938,Base!$A$2:$A$2938,$A8,Base!$D$2:$D$2938,$C8,Base!$E$2:$E$2938,"Backlog")+SUMIFS(Base!$F$2:$F$2938,Base!$A$2:$A$2938,$A8,Base!$D$2:$D$2938,$C8,Base!$E$2:$E$2938,"Doing")+SUMIFS(Base!$F$2:$F$2938,Base!$A$2:$A$2938,$A8,Base!$D$2:$D$2938,$C8,Base!$E$2:$E$2938,"Waiting Review")+SUMIFS(Base!$F$2:$F$2938,Base!$A$2:$A$2938,$A8,Base!$D$2:$D$2938,$C8,Base!$E$2:$E$2938,"Review") -> 59 | J8: =SUMIFS(Base!$G$2:$G$2938,Base!$A$2:$A$2938,$A8,Base!$D$2:$D$2938,$C8) -> 1515 | K8: =J8/60 -> 25.25 | L8: =E8+F8+G8+I8 -> 63
A9: G01-A13 | B9: G01 | C9: Sprint 03 | D9: 6 | E9: =SUMIFS(Base!$F$2:$F$2938,Base!$A$2:$A$2938,$A9,Base!$D$2:$D$2938,$C9,Base!$E$2:$E$2938,"Commit") -> 13 | F9: =SUMIFS(Base!$F$2:$F$2938,Base!$A$2:$A$2938,$A9,Base!$D$2:$D$2938,$C9,Base!$E$2:$E$2938,"MR aberta") -> 5 | G9: =SUMIFS(Base!$F$2:$F$2938,Base!$A$2:$A$2938,$A9,Base!$D$2:$D$2938,$C9,Base!$E$2:$E$2938,"MR aprovada") -> 1 | H9: =F9+G9 -> 6 | I9: =SUMIFS(Base!$F$2:$F$2938,Base!$A$2:$A$2938,$A9,Base!$D$2:$D$2938,$C9,Base!$E$2:$E$2938,"Backlog")+SUMIFS(Base!$F$2:$F$2938,Base!$A$2:$A$2938,$A9,Base!$D$2:$D$2938,$C9,Base!$E$2:$E$2938,"Doing")+SUMIFS(Base!$F$2:$F$2938,Base!$A$2:$A$2938,$A9,Base!$D$2:$D$2938,$C9,Base!$E$2:$E$2938,"Waiting Review")+SUMIFS(Base!$F$2:$F$2938,Base!$A$2:$A$2938,$A9,Base!$D$2:$D$2938,$C9,Base!$E$2:$E$2938,"Review") -> 30 | J9: =SUMIFS(Base!$G$2:$G$2938,Base!$A$2:$A$2938,$A9,Base!$D$2:$D$2938,$C9) -> 3600 | K9: =J9/60 -> 60 | L9: =E9+F9+G9+I9 -> 49
A10: G01-A13 | B10: G01 | C10: Sprint 04 | D10: 2 | E10: =SUMIFS(Base!$F$2:$F$2938,Base!$A$2:$A$2938,$A10,Base!$D$2:$D$2938,$C10,Base!$E$2:$E$2938,"Commit") -> 9 | F10: =SUMIFS(Base!$F$2:$F$2938,Base!$A$2:$A$2938,$A10,Base!$D$2:$D$2938,$C10,Base!$E$2:$E$2938,"MR aberta") -> 3 | G10: =SUMIFS(Base!$F$2:$F$2938,Base!$A$2:$A$2938,$A10,Base!$D$2:$D$2938,$C10,Base!$E$2:$E$2938,"MR aprovada") -> 2 | H10: =F10+G10 -> 5 | I10: =SUMIFS(Base!$F$2:$F$2938,Base!$A$2:$A$2938,$A10,Base!$D$2:$D$2938,$C10,Base!$E$2:$E$2938,"Backlog")+SUMIFS(Base!$F$2:$F$2938,Base!$A$2:$A$2938,$A10,Base!$D$2:$D$2938,$C10,Base!$E$2:$E$2938,"Doing")+SUMIFS(Base!$F$2:$F$2938,Base!$A$2:$A$2938,$A10,Base!$D$2:$D$2938,$C10,Base!$E$2:$E$2938,"Waiting Review")+SUMIFS(Base!$F$2:$F$2938,Base!$A$2:$A$2938,$A10,Base!$D$2:$D$2938,$C10,Base!$E$2:$E$2938,"Review") -> 10 | J10: =SUMIFS(Base!$G$2:$G$2938,Base!$A$2:$A$2938,$A10,Base!$D$2:$D$2938,$C10) -> 1200 | K10: =J10/60 -> 20 | L10: =E10+F10+G10+I10 -> 24
A11: G01-A13 | B11: G01 | C11: Sprint 05 | D11: 7 | E11: =SUMIFS(Base!$F$2:$F$2938,Base!$A$2:$A$2938,$A11,Base!$D$2:$D$2938,$C11,Base!$E$2:$E$2938,"Commit") -> 14 | F11: =SUMIFS(Base!$F$2:$F$2938,Base!$A$2:$A$2938,$A11,Base!$D$2:$D$2938,$C11,Base!$E$2:$E$2938,"MR aberta") -> 6 | G11: =SUMIFS(Base!$F$2:$F$2938,Base!$A$2:$A$2938,$A11,Base!$D$2:$D$2938,$C11,Base!$E$2:$E$2938,"MR aprovada") -> 3 | H11: =F11+G11 -> 9 | I11: =SUMIFS(Base!$F$2:$F$2938,Base!$A$2:$A$2938,$A11,Base!$D$2:$D$2938,$C11,Base!$E$2:$E$2938,"Backlog")+SUMIFS(Base!$F$2:$F$2938,Base!$A$2:$A$2938,$A11,Base!$D$2:$D$2938,$C11,Base!$E$2:$E$2938,"Doing")+SUMIFS(Base!$F$2:$F$2938,Base!$A$2:$A$2938,$A11,Base!$D$2:$D$2938,$C11,Base!$E$2:$E$2938,"Waiting Review")+SUMIFS(Base!$F$2:$F$2938,Base!$A$2:$A$2938,$A11,Base!$D$2:$D$2938,$C11,Base!$E$2:$E$2938,"Review") -> 46 | J11: =SUMIFS(Base!$G$2:$G$2938,Base!$A$2:$A$2938,$A11,Base!$D$2:$D$2938,$C11) -> 2160 | K11: =J11/60 -> 36 | L11: =E11+F11+G11+I11 -> 69
A12: G01-A14 | B12: G01 | C12: Sprint 01 | D12: 8 | E12: =SUMIFS(Base!$F$2:$F$2938,Base!$A$2:$A$2938,$A12,Base!$D$2:$D$2938,$C12,Base!$E$2:$E$2938,"Commit") -> 18 | F12: =SUMIFS(Base!$F$2:$F$2938,Base!$A$2:$A$2938,$A12,Base!$D$2:$D$2938,$C12,Base!$E$2:$E$2938,"MR aberta") -> 7 | G12: =SUMIFS(Base!$F$2:$F$2938,Base!$A$2:$A$2938,$A12,Base!$D$2:$D$2938,$C12,Base!$E$2:$E$2938,"MR aprovada") -> 7 | H12: =F12+G12 -> 14 | I12: =SUMIFS(Base!$F$2:$F$2938,Base!$A$2:$A$2938,$A12,Base!$D$2:$D$2938,$C12,Base!$E$2:$E$2938,"Backlog")+SUMIFS(Base!$F$2:$F$2938,Base!$A$2:$A$2938,$A12,Base!$D$2:$D$2938,$C12,Base!$E$2:$E$2938,"Doing")+SUMIFS(Base!$F$2:$F$2938,Base!$A$2:$A$2938,$A12,Base!$D$2:$D$2938,$C12,Base!$E$2:$E$2938,"Waiting Review")+SUMIFS(Base!$F$2:$F$2938,Base!$A$2:$A$2938,$A12,Base!$D$2:$D$2938,$C12,Base!$E$2:$E$2938,"Review") -> 49 | J12: =SUMIFS(Base!$G$2:$G$2938,Base!$A$2:$A$2938,$A12,Base!$D$2:$D$2938,$C12) -> 3060 | K12: =J12/60 -> 51 | L12: =E12+F12+G12+I12 -> 81
A13: G01-A14 | B13: G01 | C13: Sprint 02 | D13: 11 | E13: =SUMIFS(Base!$F$2:$F$2938,Base!$A$2:$A$2938,$A13,Base!$D$2:$D$2938,$C13,Base!$E$2:$E$2938,"Commit") -> 10 | F13: =SUMIFS(Base!$F$2:$F$2938,Base!$A$2:$A$2938,$A13,Base!$D$2:$D$2938,$C13,Base!$E$2:$E$2938,"MR aberta") -> 2 | G13: =SUMIFS(Base!$F$2:$F$2938,Base!$A$2:$A$2938,$A13,Base!$D$2:$D$2938,$C13,Base!$E$2:$E$2938,"MR aprovada") -> 6 | H13: =F13+G13 -> 8 | I13: =SUMIFS(Base!$F$2:$F$2938,Base!$A$2:$A$2938,$A13,Base!$D$2:$D$2938,$C13,Base!$E$2:$E$2938,"Backlog")+SUMIFS(Base!$F$2:$F$2938,Base!$A$2:$A$2938,$A13,Base!$D$2:$D$2938,$C13,Base!$E$2:$E$2938,"Doing")+SUMIFS(Base!$F$2:$F$2938,Base!$A$2:$A$2938,$A13,Base!$D$2:$D$2938,$C13,Base!$E$2:$E$2938,"Waiting Review")+SUMIFS(Base!$F$2:$F$2938,Base!$A$2:$A$2938,$A13,Base!$D$2:$D$2938,$C13,Base!$E$2:$E$2938,"Review") -> 93 | J13: =SUMIFS(Base!$G$2:$G$2938,Base!$A$2:$A$2938,$A13,Base!$D$2:$D$2938,$C13) -> 3390 | K13: =J13/60 -> 56.5 | L13: =E13+F13+G13+I13 -> 111
... A121: G03-A19 | B121: G03 | C121: Sprint 05 | D121: 4 | E121: =SUMIFS(Base!$F$2:$F$2938,Base!$A$2:$A$2938,$A121,Base!$D$2:$D$2938,$C121,Base!$E$2:$E$2938,"Commit") -> 24 | F121: =SUMIFS(Base!$F$2:$F$2938,Base!$A$2:$A$2938,$A121,Base!$D$2:$D$2938,$C121,Base!$E$2:$E$2938,"MR aberta") -> 3 | G121: =SUMIFS(Base!$F$2:$F$2938,Base!$A$2:$A$2938,$A121,Base!$D$2:$D$2938,$C121,Base!$E$2:$E$2938,"MR aprovada") -> 1 | H121: =F121+G121 -> 4 | I121: =SUMIFS(Base!$F$2:$F$2938,Base!$A$2:$A$2938,$A121,Base!$D$2:$D$2938,$C121,Base!$E$2:$E$2938,"Backlog")+SUMIFS(Base!$F$2:$F$2938,Base!$A$2:$A$2938,$A121,Base!$D$2:$D$2938,$C121,Base!$E$2:$E$2938,"Doing")+SUMIFS(Base!$F$2:$F$2938,Base!$A$2:$A$2938,$A121,Base!$D$2:$D$2938,$C121,Base!$E$2:$E$2938,"Waiting Review")+SUMIFS(Base!$F$2:$F$2938,Base!$A$2:$A$2938,$A121,Base!$D$2:$D$2938,$C121,Base!$E$2:$E$2938,"Review") -> 27 | J121: =SUMIFS(Base!$G$2:$G$2938,Base!$A$2:$A$2938,$A121,Base!$D$2:$D$2938,$C121) -> 900 | K121: =J121/60 -> 15 | L121: =E121+F121+G121+I121 -> 55

Sheet Grupo x Sprint
A1: Grupo | B1: Sprint | C1: Esforço Backlog (h) | D1: Esforço Doing (h) | E1: Esforço Waiting Review (h) | F1: Esforço Review (h) | G1: Esforço total (h) | H1: Commits | I1: MRs abertas | J1: MRs aprovadas
A2: G01 | B2: Sprint 01 | C2: =SUMIFS(Base!$H$2:$H$2938,Base!$B$2:$B$2938,$A2,Base!$D$2:$D$2938,$B2,Base!$E$2:$E$2938,"Backlog") -> 46 | D2: =SUMIFS(Base!$H$2:$H$2938,Base!$B$2:$B$2938,$A2,Base!$D$2:$D$2938,$B2,Base!$E$2:$E$2938,"Doing") -> 76.5 | E2: =SUMIFS(Base!$H$2:$H$2938,Base!$B$2:$B$2938,$A2,Base!$D$2:$D$2938,$B2,Base!$E$2:$E$2938,"Waiting Review") -> 77.5 | F2: =SUMIFS(Base!$H$2:$H$2938,Base!$B$2:$B$2938,$A2,Base!$D$2:$D$2938,$B2,Base!$E$2:$E$2938,"Review") -> 80.5 | G2: =SUM(C2:F2) -> 280.5 | H2: =SUMIFS(Base!$F$2:$F$2938,Base!$B$2:$B$2938,$A2,Base!$D$2:$D$2938,$B2,Base!$E$2:$E$2938,"Commit") -> 40 | I2: =SUMIFS(Base!$F$2:$F$2938,Base!$B$2:$B$2938,$A2,Base!$D$2:$D$2938,$B2,Base!$E$2:$E$2938,"MR aberta") -> 22 | J2: =SUMIFS(Base!$F$2:$F$2938,Base!$B$2:$B$2938,$A2,Base!$D$2:$D$2938,$B2,Base!$E$2:$E$2938,"MR aprovada") -> 17
A3: G01 | B3: Sprint 02 | C3: =SUMIFS(Base!$H$2:$H$2938,Base!$B$2:$B$2938,$A3,Base!$D$2:$D$2938,$B3,Base!$E$2:$E$2938,"Backlog") -> 44.5 | D3: =SUMIFS(Base!$H$2:$H$2938,Base!$B$2:$B$2938,$A3,Base!$D$2:$D$2938,$B3,Base!$E$2:$E$2938,"Doing") -> 65 | E3: =SUMIFS(Base!$H$2:$H$2938,Base!$B$2:$B$2938,$A3,Base!$D$2:$D$2938,$B3,Base!$E$2:$E$2938,"Waiting Review") -> 65.5 | F3: =SUMIFS(Base!$H$2:$H$2938,Base!$B$2:$B$2938,$A3,Base!$D$2:$D$2938,$B3,Base!$E$2:$E$2938,"Review") -> 53.75 | G3: =SUM(C3:F3) -> 228.75 | H3: =SUMIFS(Base!$F$2:$F$2938,Base!$B$2:$B$2938,$A3,Base!$D$2:$D$2938,$B3,Base!$E$2:$E$2938,"Commit") -> 24 | I3: =SUMIFS(Base!$F$2:$F$2938,Base!$B$2:$B$2938,$A3,Base!$D$2:$D$2938,$B3,Base!$E$2:$E$2938,"MR aberta") -> 10 | J3: =SUMIFS(Base!$F$2:$F$2938,Base!$B$2:$B$2938,$A3,Base!$D$2:$D$2938,$B3,Base!$E$2:$E$2938,"MR aprovada") -> 12
A4: G01 | B4: Sprint 03 | C4: =SUMIFS(Base!$H$2:$H$2938,Base!$B$2:$B$2938,$A4,Base!$D$2:$D$2938,$B4,Base!$E$2:$E$2938,"Backlog") -> 115.75 | D4: =SUMIFS(Base!$H$2:$H$2938,Base!$B$2:$B$2938,$A4,Base!$D$2:$D$2938,$B4,Base!$E$2:$E$2938,"Doing") -> 132 | E4: =SUMIFS(Base!$H$2:$H$2938,Base!$B$2:$B$2938,$A4,Base!$D$2:$D$2938,$B4,Base!$E$2:$E$2938,"Waiting Review") -> 115.25 | F4: =SUMIFS(Base!$H$2:$H$2938,Base!$B$2:$B$2938,$A4,Base!$D$2:$D$2938,$B4,Base!$E$2:$E$2938,"Review") -> 65.5 | G4: =SUM(C4:F4) -> 428.5 | H4: =SUMIFS(Base!$F$2:$F$2938,Base!$B$2:$B$2938,$A4,Base!$D$2:$D$2938,$B4,Base!$E$2:$E$2938,"Commit") -> 95 | I4: =SUMIFS(Base!$F$2:$F$2938,Base!$B$2:$B$2938,$A4,Base!$D$2:$D$2938,$B4,Base!$E$2:$E$2938,"MR aberta") -> 44 | J4: =SUMIFS(Base!$F$2:$F$2938,Base!$B$2:$B$2938,$A4,Base!$D$2:$D$2938,$B4,Base!$E$2:$E$2938,"MR aprovada") -> 39
A5: G01 | B5: Sprint 04 | C5: =SUMIFS(Base!$H$2:$H$2938,Base!$B$2:$B$2938,$A5,Base!$D$2:$D$2938,$B5,Base!$E$2:$E$2938,"Backlog") -> 61 | D5: =SUMIFS(Base!$H$2:$H$2938,Base!$B$2:$B$2938,$A5,Base!$D$2:$D$2938,$B5,Base!$E$2:$E$2938,"Doing") -> 101 | E5: =SUMIFS(Base!$H$2:$H$2938,Base!$B$2:$B$2938,$A5,Base!$D$2:$D$2938,$B5,Base!$E$2:$E$2938,"Waiting Review") -> 112.5 | F5: =SUMIFS(Base!$H$2:$H$2938,Base!$B$2:$B$2938,$A5,Base!$D$2:$D$2938,$B5,Base!$E$2:$E$2938,"Review") -> 150.5 | G5: =SUM(C5:F5) -> 425 | H5: =SUMIFS(Base!$F$2:$F$2938,Base!$B$2:$B$2938,$A5,Base!$D$2:$D$2938,$B5,Base!$E$2:$E$2938,"Commit") -> 154 | I5: =SUMIFS(Base!$F$2:$F$2938,Base!$B$2:$B$2938,$A5,Base!$D$2:$D$2938,$B5,Base!$E$2:$E$2938,"MR aberta") -> 25 | J5: =SUMIFS(Base!$F$2:$F$2938,Base!$B$2:$B$2938,$A5,Base!$D$2:$D$2938,$B5,Base!$E$2:$E$2938,"MR aprovada") -> 25
A6: G01 | B6: Sprint 05 | C6: =SUMIFS(Base!$H$2:$H$2938,Base!$B$2:$B$2938,$A6,Base!$D$2:$D$2938,$B6,Base!$E$2:$E$2938,"Backlog") -> 178 | D6: =SUMIFS(Base!$H$2:$H$2938,Base!$B$2:$B$2938,$A6,Base!$D$2:$D$2938,$B6,Base!$E$2:$E$2938,"Doing") -> 177 | E6: =SUMIFS(Base!$H$2:$H$2938,Base!$B$2:$B$2938,$A6,Base!$D$2:$D$2938,$B6,Base!$E$2:$E$2938,"Waiting Review") -> 170.75 | F6: =SUMIFS(Base!$H$2:$H$2938,Base!$B$2:$B$2938,$A6,Base!$D$2:$D$2938,$B6,Base!$E$2:$E$2938,"Review") -> 171 | G6: =SUM(C6:F6) -> 696.75 | H6: =SUMIFS(Base!$F$2:$F$2938,Base!$B$2:$B$2938,$A6,Base!$D$2:$D$2938,$B6,Base!$E$2:$E$2938,"Commit") -> 147 | I6: =SUMIFS(Base!$F$2:$F$2938,Base!$B$2:$B$2938,$A6,Base!$D$2:$D$2938,$B6,Base!$E$2:$E$2938,"MR aberta") -> 41 | J6: =SUMIFS(Base!$F$2:$F$2938,Base!$B$2:$B$2938,$A6,Base!$D$2:$D$2938,$B6,Base!$E$2:$E$2938,"MR aprovada") -> 39
A7: G02 | B7: Sprint 01 | C7: =SUMIFS(Base!$H$2:$H$2938,Base!$B$2:$B$2938,$A7,Base!$D$2:$D$2938,$B7,Base!$E$2:$E$2938,"Backlog") -> 79.5 | D7: =SUMIFS(Base!$H$2:$H$2938,Base!$B$2:$B$2938,$A7,Base!$D$2:$D$2938,$B7,Base!$E$2:$E$2938,"Doing") -> 95 | E7: =SUMIFS(Base!$H$2:$H$2938,Base!$B$2:$B$2938,$A7,Base!$D$2:$D$2938,$B7,Base!$E$2:$E$2938,"Waiting Review") -> 74.75 | F7: =SUMIFS(Base!$H$2:$H$2938,Base!$B$2:$B$2938,$A7,Base!$D$2:$D$2938,$B7,Base!$E$2:$E$2938,"Review") -> 60.5 | G7: =SUM(C7:F7) -> 309.75 | H7: =SUMIFS(Base!$F$2:$F$2938,Base!$B$2:$B$2938,$A7,Base!$D$2:$D$2938,$B7,Base!$E$2:$E$2938,"Commit") -> 73 | I7: =SUMIFS(Base!$F$2:$F$2938,Base!$B$2:$B$2938,$A7,Base!$D$2:$D$2938,$B7,Base!$E$2:$E$2938,"MR aberta") -> 24 | J7: =SUMIFS(Base!$F$2:$F$2938,Base!$B$2:$B$2938,$A7,Base!$D$2:$D$2938,$B7,Base!$E$2:$E$2938,"MR aprovada") -> 19
A8: G02 | B8: Sprint 02 | C8: =SUMIFS(Base!$H$2:$H$2938,Base!$B$2:$B$2938,$A8,Base!$D$2:$D$2938,$B8,Base!$E$2:$E$2938,"Backlog") -> 151.5 | D8: =SUMIFS(Base!$H$2:$H$2938,Base!$B$2:$B$2938,$A8,Base!$D$2:$D$2938,$B8,Base!$E$2:$E$2938,"Doing") -> 174.5 | E8: =SUMIFS(Base!$H$2:$H$2938,Base!$B$2:$B$2938,$A8,Base!$D$2:$D$2938,$B8,Base!$E$2:$E$2938,"Waiting Review") -> 177.75 | F8: =SUMIFS(Base!$H$2:$H$2938,Base!$B$2:$B$2938,$A8,Base!$D$2:$D$2938,$B8,Base!$E$2:$E$2938,"Review") -> 186.5 | G8: =SUM(C8:F8) -> 690.25 | H8: =SUMIFS(Base!$F$2:$F$2938,Base!$B$2:$B$2938,$A8,Base!$D$2:$D$2938,$B8,Base!$E$2:$E$2938,"Commit") -> 109 | I8: =SUMIFS(Base!$F$2:$F$2938,Base!$B$2:$B$2938,$A8,Base!$D$2:$D$2938,$B8,Base!$E$2:$E$2938,"MR aberta") -> 25 | J8: =SUMIFS(Base!$F$2:$F$2938,Base!$B$2:$B$2938,$A8,Base!$D$2:$D$2938,$B8,Base!$E$2:$E$2938,"MR aprovada") -> 29
A9: G02 | B9: Sprint 03 | C9: =SUMIFS(Base!$H$2:$H$2938,Base!$B$2:$B$2938,$A9,Base!$D$2:$D$2938,$B9,Base!$E$2:$E$2938,"Backlog") -> 175.5 | D9: =SUMIFS(Base!$H$2:$H$2938,Base!$B$2:$B$2938,$A9,Base!$D$2:$D$2938,$B9,Base!$E$2:$E$2938,"Doing") -> 221.25 | E9: =SUMIFS(Base!$H$2:$H$2938,Base!$B$2:$B$2938,$A9,Base!$D$2:$D$2938,$B9,Base!$E$2:$E$2938,"Waiting Review") -> 203.25 | F9: =SUMIFS(Base!$H$2:$H$2938,Base!$B$2:$B$2938,$A9,Base!$D$2:$D$2938,$B9,Base!$E$2:$E$2938,"Review") -> 204 | G9: =SUM(C9:F9) -> 804 | H9: =SUMIFS(Base!$F$2:$F$2938,Base!$B$2:$B$2938,$A9,Base!$D$2:$D$2938,$B9,Base!$E$2:$E$2938,"Commit") -> 164 | I9: =SUMIFS(Base!$F$2:$F$2938,Base!$B$2:$B$2938,$A9,Base!$D$2:$D$2938,$B9,Base!$E$2:$E$2938,"MR aberta") -> 44 | J9: =SUMIFS(Base!$F$2:$F$2938,Base!$B$2:$B$2938,$A9,Base!$D$2:$D$2938,$B9,Base!$E$2:$E$2938,"MR aprovada") -> 40
A10: G02 | B10: Sprint 04 | C10: =SUMIFS(Base!$H$2:$H$2938,Base!$B$2:$B$2938,$A10,Base!$D$2:$D$2938,$B10,Base!$E$2:$E$2938,"Backlog") -> 190.5 | D10: =SUMIFS(Base!$H$2:$H$2938,Base!$B$2:$B$2938,$A10,Base!$D$2:$D$2938,$B10,Base!$E$2:$E$2938,"Doing") -> 209.5 | E10: =SUMIFS(Base!$H$2:$H$2938,Base!$B$2:$B$2938,$A10,Base!$D$2:$D$2938,$B10,Base!$E$2:$E$2938,"Waiting Review") -> 193.5 | F10: =SUMIFS(Base!$H$2:$H$2938,Base!$B$2:$B$2938,$A10,Base!$D$2:$D$2938,$B10,Base!$E$2:$E$2938,"Review") -> 184.5 | G10: =SUM(C10:F10) -> 778 | H10: =SUMIFS(Base!$F$2:$F$2938,Base!$B$2:$B$2938,$A10,Base!$D$2:$D$2938,$B10,Base!$E$2:$E$2938,"Commit") -> 237 | I10: =SUMIFS(Base!$F$2:$F$2938,Base!$B$2:$B$2938,$A10,Base!$D$2:$D$2938,$B10,Base!$E$2:$E$2938,"MR aberta") -> 48 | J10: =SUMIFS(Base!$F$2:$F$2938,Base!$B$2:$B$2938,$A10,Base!$D$2:$D$2938,$B10,Base!$E$2:$E$2938,"MR aprovada") -> 48
A11: G02 | B11: Sprint 05 | C11: =SUMIFS(Base!$H$2:$H$2938,Base!$B$2:$B$2938,$A11,Base!$D$2:$D$2938,$B11,Base!$E$2:$E$2938,"Backlog") -> 263 | D11: =SUMIFS(Base!$H$2:$H$2938,Base!$B$2:$B$2938,$A11,Base!$D$2:$D$2938,$B11,Base!$E$2:$E$2938,"Doing") -> 264 | E11: =SUMIFS(Base!$H$2:$H$2938,Base!$B$2:$B$2938,$A11,Base!$D$2:$D$2938,$B11,Base!$E$2:$E$2938,"Waiting Review") -> 258.5 | F11: =SUMIFS(Base!$H$2:$H$2938,Base!$B$2:$B$2938,$A11,Base!$D$2:$D$2938,$B11,Base!$E$2:$E$2938,"Review") -> 251 | G11: =SUM(C11:F11) -> 1036.5 | H11: =SUMIFS(Base!$F$2:$F$2938,Base!$B$2:$B$2938,$A11,Base!$D$2:$D$2938,$B11,Base!$E$2:$E$2938,"Commit") -> 344 | I11: =SUMIFS(Base!$F$2:$F$2938,Base!$B$2:$B$2938,$A11,Base!$D$2:$D$2938,$B11,Base!$E$2:$E$2938,"MR aberta") -> 62 | J11: =SUMIFS(Base!$F$2:$F$2938,Base!$B$2:$B$2938,$A11,Base!$D$2:$D$2938,$B11,Base!$E$2:$E$2938,"MR aprovada") -> 56
A12: G03 | B12: Sprint 01 | C12: =SUMIFS(Base!$H$2:$H$2938,Base!$B$2:$B$2938,$A12,Base!$D$2:$D$2938,$B12,Base!$E$2:$E$2938,"Backlog") -> 81.25 | D12: =SUMIFS(Base!$H$2:$H$2938,Base!$B$2:$B$2938,$A12,Base!$D$2:$D$2938,$B12,Base!$E$2:$E$2938,"Doing") -> 88.5 | E12: =SUMIFS(Base!$H$2:$H$2938,Base!$B$2:$B$2938,$A12,Base!$D$2:$D$2938,$B12,Base!$E$2:$E$2938,"Waiting Review") -> 88 | F12: =SUMIFS(Base!$H$2:$H$2938,Base!$B$2:$B$2938,$A12,Base!$D$2:$D$2938,$B12,Base!$E$2:$E$2938,"Review") -> 85.5 | G12: =SUM(C12:F12) -> 343.25 | H12: =SUMIFS(Base!$F$2:$F$2938,Base!$B$2:$B$2938,$A12,Base!$D$2:$D$2938,$B12,Base!$E$2:$E$2938,"Commit") -> 68 | I12: =SUMIFS(Base!$F$2:$F$2938,Base!$B$2:$B$2938,$A12,Base!$D$2:$D$2938,$B12,Base!$E$2:$E$2938,"MR aberta") -> 21 | J12: =SUMIFS(Base!$F$2:$F$2938,Base!$B$2:$B$2938,$A12,Base!$D$2:$D$2938,$B12,Base!$E$2:$E$2938,"MR aprovada") -> 19
A13: G03 | B13: Sprint 02 | C13: =SUMIFS(Base!$H$2:$H$2938,Base!$B$2:$B$2938,$A13,Base!$D$2:$D$2938,$B13,Base!$E$2:$E$2938,"Backlog") -> 67.5 | D13: =SUMIFS(Base!$H$2:$H$2938,Base!$B$2:$B$2938,$A13,Base!$D$2:$D$2938,$B13,Base!$E$2:$E$2938,"Doing") -> 71.5 | E13: =SUMIFS(Base!$H$2:$H$2938,Base!$B$2:$B$2938,$A13,Base!$D$2:$D$2938,$B13,Base!$E$2:$E$2938,"Waiting Review") -> 70.25 | F13: =SUMIFS(Base!$H$2:$H$2938,Base!$B$2:$B$2938,$A13,Base!$D$2:$D$2938,$B13,Base!$E$2:$E$2938,"Review") -> 63.25 | G13: =SUM(C13:F13) -> 272.5 | H13: =SUMIFS(Base!$F$2:$F$2938,Base!$B$2:$B$2938,$A13,Base!$D$2:$D$2938,$B13,Base!$E$2:$E$2938,"Commit") -> 46 | I13: =SUMIFS(Base!$F$2:$F$2938,Base!$B$2:$B$2938,$A13,Base!$D$2:$D$2938,$B13,Base!$E$2:$E$2938,"MR aberta") -> 14 | J13: =SUMIFS(Base!$F$2:$F$2938,Base!$B$2:$B$2938,$A13,Base!$D$2:$D$2938,$B13,Base!$E$2:$E$2938,"MR aprovada") -> 14
... A16: G03 | B16: Sprint 05 | C16: =SUMIFS(Base!$H$2:$H$2938,Base!$B$2:$B$2938,$A16,Base!$D$2:$D$2938,$B16,Base!$E$2:$E$2938,"Backlog") -> 115.75 | D16: =SUMIFS(Base!$H$2:$H$2938,Base!$B$2:$B$2938,$A16,Base!$D$2:$D$2938,$B16,Base!$E$2:$E$2938,"Doing") -> 112.5 | E16: =SUMIFS(Base!$H$2:$H$2938,Base!$B$2:$B$2938,$A16,Base!$D$2:$D$2938,$B16,Base!$E$2:$E$2938,"Waiting Review") -> 108.5 | F16: =SUMIFS(Base!$H$2:$H$2938,Base!$B$2:$B$2938,$A16,Base!$D$2:$D$2938,$B16,Base!$E$2:$E$2938,"Review") -> 115.5 | G16: =SUM(C16:F16) -> 452.25 | H16: =SUMIFS(Base!$F$2:$F$2938,Base!$B$2:$B$2938,$A16,Base!$D$2:$D$2938,$B16,Base!$E$2:$E$2938,"Commit") -> 201 | I16: =SUMIFS(Base!$F$2:$F$2938,Base!$B$2:$B$2938,$A16,Base!$D$2:$D$2938,$B16,Base!$E$2:$E$2938,"MR aberta") -> 35 | J16: =SUMIFS(Base!$F$2:$F$2938,Base!$B$2:$B$2938,$A16,Base!$D$2:$D$2938,$B16,Base!$E$2:$E$2938,"MR aprovada") -> 32

Sheet Base
A1: Pessoa | B1: Grupo | C1: Data | D1: Sprint | E1: Tipo de registro | F1: Quantidade | G1: Esforço (min) | H1: Esforço (h) | I1: Integrante identificado
A2: G01-A12 | B2: G01 | C2: 2026-04-27 | D2: Sprint 01 | E2: Backlog | F2: 8 | G2: 600 | H2: =G2/60 -> 10 | I2: Sim
A3: G01-A12 | B3: G01 | C3: 2026-04-27 | D3: Sprint 01 | E3: Doing | F3: 6 | G3: 420 | H3: =G3/60 -> 7 | I3: Sim
A4: G01-A12 | B4: G01 | C4: 2026-04-27 | D4: Sprint 01 | E4: Waiting Review | F4: 3 | G4: 180 | H4: =G4/60 -> 3 | I4: Sim
A5: G01-A12 | B5: G01 | C5: 2026-04-27 | D5: Sprint 01 | E5: Review | F5: 1 | G5: 60 | H5: =G5/60 -> 1 | I5: Sim
A6: G01-A12 | B6: G01 | C6: 2026-04-27 | D6: Sprint 01 | E6: Commit | F6: 3 | G6: 0 | H6: =G6/60 -> 0 | I6: Sim
A7: G01-A12 | B7: G01 | C7: 2026-04-27 | D7: Sprint 01 | E7: MR aberta | F7: 1 | G7: 0 | H7: =G7/60 -> 0 | I7: Sim
A8: G01-A12 | B8: G01 | C8: 2026-04-27 | D8: Sprint 01 | E8: MR aprovada | F8: 1 | G8: 0 | H8: =G8/60 -> 0 | I8: Sim
A9: G01-A12 | B9: G01 | C9: 2026-04-28 | D9: Sprint 01 | E9: Backlog | F9: 2 | G9: 120 | H9: =G9/60 -> 2 | I9: Sim
A10: G01-A12 | B10: G01 | C10: 2026-04-28 | D10: Sprint 01 | E10: Doing | F10: 1 | G10: 60 | H10: =G10/60 -> 1 | I10: Sim
A11: G01-A12 | B11: G01 | C11: 2026-04-28 | D11: Sprint 01 | E11: Commit | F11: 2 | G11: 0 | H11: =G11/60 -> 0 | I11: Sim
A12: G01-A12 | B12: G01 | C12: 2026-04-28 | D12: Sprint 01 | E12: MR aberta | F12: 1 | G12: 0 | H12: =G12/60 -> 0 | I12: Sim
A13: G01-A12 | B13: G01 | C13: 2026-04-29 | D13: Sprint 01 | E13: Doing | F13: 3 | G13: 240 | H13: =G13/60 -> 4 | I13: Sim
... A2814: G03-A19 | B2814: G03 | C2814: 2026-06-25 | D2814: Sprint 05 | E2814: MR aprovada | F2814: 1 | G2814: 0 | H2814: =G2814/60 -> 0 | I2814: Sim
A2815: [bot] | C2815: 2026-04-27 | D2815: Sprint 01 | E2815: Commit | F2815: 2 | G2815: 0 | H2815: =G2815/60 -> 0 | I2815: Não
A2816: [bot] | C2816: 2026-04-28 | D2816: Sprint 01 | E2816: Commit | F2816: 1 | G2816: 0 | H2816: =G2816/60 -> 0 | I2816: Não
A2817: [bot] | C2817: 2026-04-29 | D2817: Sprint 01 | E2817: Commit | F2817: 2 | G2817: 0 | H2817: =G2817/60 -> 0 | I2817: Não
A2818: [bot] | C2818: 2026-05-11 | D2818: Sprint 02 | E2818: Commit | F2818: 1 | G2818: 0 | H2818: =G2818/60 -> 0 | I2818: Não
A2819: [bot] | C2819: 2026-05-12 | D2819: Sprint 02 | E2819: Commit | F2819: 1 | G2819: 0 | H2819: =G2819/60 -> 0 | I2819: Não
A2820: [bot] | C2820: 2026-05-19 | D2820: Sprint 03 | E2820: Commit | F2820: 1 | G2820: 0 | H2820: =G2820/60 -> 0 | I2820: Não
A2821: [bot] | C2821: 2026-05-20 | D2821: Sprint 03 | E2821: Commit | F2821: 1 | G2821: 0 | H2821: =G2821/60 -> 0 | I2821: Não
A2822: [bot] | C2822: 2026-05-21 | D2822: Sprint 03 | E2822: Commit | F2822: 4 | G2822: 0 | H2822: =G2822/60 -> 0 | I2822: Não
A2823: [bot] | C2823: 2026-05-25 | D2823: Sprint 03 | E2823: Commit | F2823: 2 | G2823: 0 | H2823: =G2823/60 -> 0 | I2823: Não
A2824: [bot] | C2824: 2026-05-26 | D2824: Sprint 03 | E2824: Commit | F2824: 4 | G2824: 0 | H2824: =G2824/60 -> 0 | I2824: Não
A2825: [bot] | C2825: 2026-05-27 | D2825: Sprint 03 | E2825: Commit | F2825: 3 | G2825: 0 | H2825: =G2825/60 -> 0 | I2825: Não
A2826: [bot] | C2826: 2026-05-28 | D2826: Sprint 03 | E2826: Commit | F2826: 1 | G2826: 0 | H2826: =G2826/60 -> 0 | I2826: Não
... A2938: [externo] | C2938: 2026-06-26 | D2938: Sprint 05 | E2938: Commit | F2938: 1 | G2938: 0 | H2938: =G2938/60 -> 0 | I2938: Não

Sheet Cartões
A1: grupo | B1: cartao | C1: titulo | D1: sprint | E1: situacao | F1: responsavel | G1: papel | H1: vinculo | I1: rotulos | J1: rotulos_nucleo | K1: rotulos_perifericos | L1: rotulos_outros | M1: motivo | N1: criado_em | O1: fechado_em | P1: prazo_em
A2: G01 | B2: 1 | C2: Análise das 5 forças de Porter | D2: Sprint 01 | E2: closed | F2: G01-A13 | G2: maintainer | H2: Integrante identificado | I2: ART.01;BUG;DOCUMENTATION;NEGÓCIOS;P | J2: BUG; NEGÓCIOS | K2: DOCUMENTATION | L2: ART.01; P | M2: rótulo de núcleo: BUG, NEGÓCIOS | N2: 2026-04-22 | O2: 2026-04-22
A3: G01 | B3: 2 | C3: Redação de introdução - Seção 1 | D3: Sprint 01 | E3: closed | F3: [externo] | H3: Externo | I3: ART.01;DOCUMENTATION;M | K3: DOCUMENTATION | L3: ART.01; M | M3: sem núcleo; rótulo periférico: DOCUMENTATION | N3: 2026-04-22 | O3: 2026-04-27
A4: G01 | B4: 3 | C4: Análise das 5 Forças de Porter - Seção 2.1.1 | D4: Sprint 01 | E4: closed | F4: G01-A13 | G4: maintainer | H4: Integrante identificado | I4: ART.01;M;NEGÓCIOS | J4: NEGÓCIOS | L4: ART.01; M | M4: rótulo de núcleo: NEGÓCIOS | N4: 2026-04-22 | O4: 2026-04-24
A5: G01 | B5: 4 | C5: Matriz SWOT - Seção 2.1.2 | D5: Sprint 01 | E5: closed | F5: G01-A23 | G5: maintainer | H5: Integrante identificado | I5: ART.01;M;NEGÓCIOS | J5: NEGÓCIOS | L5: ART.01; M | M5: rótulo de núcleo: NEGÓCIOS | N5: 2026-04-22 | O5: 2026-05-02
A6: G01 | B6: 5 | C6: Descrição da solução - Seção 2.1.3 | D6: Sprint 01 | E6: closed | F6: G01-A15 | G6: maintainer | H6: Integrante identificado | I6: DOCUMENTATION;M | K6: DOCUMENTATION | L6: M | M6: sem núcleo; rótulo periférico: DOCUMENTATION | N6: 2026-04-22 | O6: 2026-05-04
A7: G01 | B7: 6 | C7: Canvas de proposta de valor - Seção 2.1.4 | D7: Sprint 01 | E7: closed | F7: G01-A17 | G7: maintainer | H7: Integrante identificado | I7: ART.01;DOCUMENTATION;M;NEGÓCIOS | J7: NEGÓCIOS | K7: DOCUMENTATION | L7: ART.01; M | M7: rótulo de núcleo: NEGÓCIOS | N7: 2026-04-22 | O7: 2026-05-02
A8: G01 | B8: 7 | C8: Matriz de Riscos - Seção 2.1.5 | D8: Sprint 01 | E8: closed | F8: G01-A14 | G8: maintainer | H8: Integrante identificado | I8: ART.01;M;NEGÓCIOS | J8: NEGÓCIOS | L8: ART.01; M | M8: rótulo de núcleo: NEGÓCIOS | N8: 2026-04-22 | O8: 2026-05-02
A9: G01 | B9: 8 | C9: Criação de personas - Seção 2.2 | D9: Sprint 01 | E9: closed | F9: [externo] | H9: Externo | I9: ART.02;DESIGN;M | J9: DESIGN | L9: ART.02; M | M9: rótulo de núcleo: DESIGN | N9: 2026-04-23 | O9: 2026-05-01
A10: G01 | B10: 9 | C10: Criação de User Storie 1 - Seção 2.3 | D10: Sprint 01 | E10: closed | F10: [externo] | H10: Externo | I10: ART.02;DESIGN;G | J10: DESIGN | L10: ART.02; G | M10: rótulo de núcleo: DESIGN | N10: 2026-04-23 | O10: 2026-05-01
A11: G01 | B11: 10 | C11: Criação de User Storie 2 - Seção 2.3 | D11: Sprint 01 | E11: closed | F11: G01-A23 | G11: maintainer | H11: Integrante identificado | I11: ART.02;DESIGN;M | J11: DESIGN | L11: ART.02; M | M11: rótulo de núcleo: DESIGN | N11: 2026-04-23 | O11: 2026-05-01
A12: G01 | B12: 11 | C12: Requisitos Funcionais - Seção 3.1 | D12: Sprint 01 | E12: closed | F12: G01-A15 | G12: maintainer | H12: Integrante identificado | I12: ART.03;CODE;M | J12: CODE | L12: ART.03; M | M12: rótulo de núcleo: CODE | N12: 2026-04-23 | O12: 2026-05-01
A13: G01 | B13: 12 | C13: Regras de negócio - Seção 3.1.2 | D13: Sprint 01 | E13: closed | F13: G01-A17 | G13: maintainer | H13: Integrante identificado | I13: ART.03;CODE;M | J13: CODE | L13: ART.03; M | M13: rótulo de núcleo: CODE | N13: 2026-04-23 | O13: 2026-05-02
A14: G01 | B14: 13 | C14: Requisitos Não Funcionais (ISO 25010) - Seção 3.1.2 | D14: Sprint 01 | E14: closed | F14: G01-A16 | G14: maintainer | H14: Integrante identificado | I14: ART.03;CODE;M | J14: CODE | L14: ART.03; M | M14: rótulo de núcleo: CODE | N14: 2026-04-23 | O14: 2026-05-01
A15: G01 | B15: 14 | C15: Diagrama de casos de uso - Seção 3.2.2 | D15: Sprint 01 | E15: closed | F15: G01-A13 | G15: maintainer | H15: Integrante identificado | I15: ART.03;CODE;M | J15: CODE | L15: ART.03; M | M15: rótulo de núcleo: CODE | N15: 2026-04-23 | O15: 2026-05-01
A16: G01 | B16: 15 | C16: Análise SWOT( Informações) | D16: Sprint 01 | E16: closed | F16: G01-A23 | G16: maintainer | H16: Integrante identificado | I16: ART.01;NEGÓCIOS;P | J16: NEGÓCIOS | L16: ART.01; P | M16: rótulo de núcleo: NEGÓCIOS | N16: 2026-04-23 | O16: 2026-04-23 | P16: 2026-04-23
A17: G01 | B17: 16 | C17: User Case - Seção 3.2.2 | D17: Sprint 01 | E17: closed | F17: G01-A14 | G17: maintainer | H17: Integrante identificado | I17: ART.03;CODE;M | J17: CODE | L17: ART.03; M | M17: rótulo de núcleo: CODE | N17: 2026-04-23 | O17: 2026-05-01
A18: G01 | B18: 17 | C18: Criação da imagem da matriz SWOT | D18: Sprint 01 | E18: closed | F18: G01-A15 | G18: maintainer | H18: Integrante identificado | I18: ART.01;DESIGN;M | J18: DESIGN | L18: ART.01; M | M18: rótulo de núcleo: DESIGN | N18: 2026-04-23 | O18: 2026-04-28
A19: G01 | B19: 18 | C19: Criação de imagem da Matriz de risco | D19: Sprint 01 | E19: closed | F19: G01-A14 | G19: maintainer | H19: Integrante identificado | I19: ART.01;M;NEGÓCIOS | J19: NEGÓCIOS | L19: ART.01; M | M19: rótulo de núcleo: NEGÓCIOS | N19: 2026-04-24 | O19: 2026-05-02
A20: G01 | B20: 19 | C20: Fluxo de telas | D20: Sprint 01 | E20: closed | F20: G01-A14 | G20: maintainer | H20: Integrante identificado | I20: CODE;DESIGN;P | J20: CODE; DESIGN | L20: P | M20: rótulo de núcleo: CODE, DESIGN | N20: 2026-04-27 | O20: 2026-05-02
A21: G01 | B21: 20 | C21: Criar as Personas | D21: Sprint 01 | E21: closed | F21: G01-A15 | G21: maintainer | H21: Integrante identificado | I21: ART.01;DOCUMENTATION;M | K21: DOCUMENTATION | L21: ART.01; M | M21: sem núcleo; rótulo periférico: DOCUMENTATION | N21: 2026-04-27 | O21: 2026-04-29
A22: G01 | B22: 21 | C22: Criação da imagem das 5 forças de Poter's | D22: Sprint 01 | E22: closed | F22: G01-A12 | G22: maintainer | H22: Integrante identificado | I22: ART.01;DESIGN;DOCUMENTATION;M;NEGÓCIOS | J22: DESIGN; NEGÓCIOS | K22: DOCUMENTATION | L22: ART.01; M | M22: rótulo de núcleo: DESIGN, NEGÓCIOS | N22: 2026-04-27 | O22: 2026-05-02
A23: G01 | B23: 22 | C23: Identação e modificação para voz passiva analítica da análise das 5 forças de Poter's | D23: Sprint 01 | E23: closed | F23: G01-A12 | G23: maintainer | H23: Integrante identificado | I23: ART.01;DOCUMENTATION;M;NEGÓCIOS | J23: NEGÓCIOS | K23: DOCUMENTATION | L23: ART.01; M | M23: rótulo de núcleo: NEGÓCIOS | N23: 2026-04-27 | O23: 2026-05-02
A24: G01 | B24: 23 | C24: Idealização do fluxo de telas | D24: (sem sprint) | E24: closed | F24: G01-A16 | G24: maintainer | H24: Integrante identificado | I24: ART.01;DESIGN;M | J24: DESIGN | L24: ART.01; M | M24: rótulo de núcleo: DESIGN | N24: 2026-04-27 | O24: 2026-04-28
A25: G01 | B25: 24 | C25: Descrição da solução - 2.1.3 | D25: (sem sprint) | E25: closed | F25: G01-A13 | G25: maintainer | H25: Integrante identificado | I25: ART.01;DOCUMENTATION;G;NEGÓCIOS | J25: NEGÓCIOS | K25: DOCUMENTATION | L25: ART.01; G | M25: rótulo de núcleo: NEGÓCIOS | N25: 2026-04-27 | O25: 2026-05-02
A26: G01 | B26: 25 | C26: Criação da Persona 3 - Coordenador | D26: Sprint 01 | E26: closed | F26: G01-A12 | G26: maintainer | H26: Integrante identificado | I26: ART.01;DESIGN;DOCUMENTATION;M | J26: DESIGN | K26: DOCUMENTATION | L26: ART.01; M | M26: rótulo de núcleo: DESIGN | N26: 2026-04-28 | O26: 2026-05-02
A27: G01 | B27: 26 | C27: Criação dos templates das 3 personas | D27: Sprint 01 | E27: closed | F27: G01-A12 | G27: maintainer | H27: Integrante identificado | I27: ART.01;DESIGN;DOCUMENTATION;G | J27: DESIGN | K27: DOCUMENTATION | L27: ART.01; G | M27: rótulo de núcleo: DESIGN | N27: 2026-04-28 | O27: 2026-05-02
A28: G01 | B28: 27 | C28: Criar a imagem do canvas de valor | D28: Sprint 01 | E28: closed | F28: G01-A15 | G28: maintainer | H28: Integrante identificado | I28: ART.01;DESIGN;DOCUMENTATION;NEGÓCIOS;P | J28: DESIGN; NEGÓCIOS | K28: DOCUMENTATION | L28: ART.01; P | M28: rótulo de núcleo: DESIGN, NEGÓCIOS | N28: 2026-04-28 | O28: 2026-05-01
A29: G01 | B29: 28 | C29: Preencher a seção 2.2 do wad refrente as personas da solução | D29: Sprint 01 | E29: closed | F29: G01-A12 | G29: maintainer | H29: Integrante identificado | I29: ART.01;DESIGN;DOCUMENTATION;M | J29: DESIGN | K29: DOCUMENTATION | L29: ART.01; M | M29: rótulo de núcleo: DESIGN | N29: 2026-04-28 | O29: 2026-05-02
A30: G01 | B30: 29 | C30: Relacionar Requisitos Funcionais com Regras de Negócios na Seção 3.1.2 | D30: Sprint 01 | E30: closed | F30: G01-A15 | G30: maintainer | H30: Integrante identificado | I30: ART.03;CODE;DOCUMENTATION;M | J30: CODE | K30: DOCUMENTATION | L30: ART.03; M | M30: rótulo de núcleo: CODE | N30: 2026-04-28 | O30: 2026-05-04
A31: G01 | B31: 30 | C31: Use Case 2 - Seção 3.2.2 | D31: Sprint 01 | E31: closed | F31: G01-A14 | G31: maintainer | H31: Integrante identificado | I31: ART.03;CODE;DOCUMENTATION;M | J31: CODE | K31: DOCUMENTATION | L31: ART.03; M | M31: rótulo de núcleo: CODE | N31: 2026-04-29 | O31: 2026-05-01
A32: G01 | B32: 31 | C32: Redigir User Stories no WAD - Seção 2.3 | D32: Sprint 01 | E32: closed | F32: [externo] | H32: Externo | I32: ART.02;DESIGN;DOCUMENTATION;M | J32: DESIGN | K32: DOCUMENTATION | L32: ART.02; M | M32: rótulo de núcleo: DESIGN | N32: 2026-04-29 | O32: 2026-05-02
A33: G01 | B33: 32 | C33: Organizar documents e assets | D33: Sprint 01 | E33: closed | F33: G01-A17 | G33: maintainer | H33: Integrante identificado | I33: DOCUMENTATION;P | K33: DOCUMENTATION | L33: P | M33: sem núcleo; rótulo periférico: DOCUMENTATION | N33: 2026-04-29 | O33: 2026-05-02
A34: G01 | B34: 33 | C34: Introdução da Regra de negócio | D34: Sprint 01 | E34: closed | F34: G01-A17 | G34: maintainer | H34: Integrante identificado | I34: DOCUMENTATION;P | K34: DOCUMENTATION | L34: P | M34: sem núcleo; rótulo periférico: DOCUMENTATION | N34: 2026-04-29 | O34: 2026-05-02
A35: G01 | B35: 34 | C35: Use Case alterações | D35: Sprint 01 | E35: closed | F35: G01-A14 | G35: maintainer | H35: Integrante identificado | I35: ART.03;CODE;DOCUMENTATION;M | J35: CODE | K35: DOCUMENTATION | L35: ART.03; M | M35: rótulo de núcleo: CODE | N35: 2026-04-30 | O35: 2026-05-01
A36: G01 | B36: 35 | C36: Realizar a revisão do wad | D36: Sprint 01 | E36: closed | F36: G01-A15 | G36: maintainer | H36: Integrante identificado | I36: DOCUMENTATION;M | K36: DOCUMENTATION | L36: M | M36: sem núcleo; rótulo periférico: DOCUMENTATION | N36: 2026-04-30 | O36: 2026-05-01
A37: G01 | B37: 36 | C37: Realizar Identação dosartefatos 1, 2 e 3 do wad | D37: Sprint 01 | E37: closed | F37: G01-A12 | G37: maintainer | H37: Integrante identificado | I37: ART.01;ART.02;ART.03;DOCUMENTATION;P | K37: DOCUMENTATION | L37: ART.01; ART.02; ART.03; P | M37: sem núcleo; rótulo periférico: DOCUMENTATION | N37: 2026-04-30 | O37: 2026-05-02
A38: G01 | B38: 37 | C38: Use Case - alteração de diagramas de caso de uso | D38: Sprint 01 | E38: closed | F38: G01-A14 | G38: maintainer | H38: Integrante identificado | I38: ART.03;CODE;DOCUMENTATION;G | J38: CODE | K38: DOCUMENTATION | L38: ART.03; G | M38: rótulo de núcleo: CODE | N38: 2026-04-30 | O38: 2026-05-01
A39: G01 | B39: 38 | C39: Use Case - alteração de imagens | D39: Sprint 01 | E39: closed | F39: G01-A12 | G39: maintainer | H39: Integrante identificado | I39: ART.03;CODE;DOCUMENTATION;M | J39: CODE | K39: DOCUMENTATION | L39: ART.03; M | M39: rótulo de núcleo: CODE | N39: 2026-04-30 | O39: 2026-05-02
A40: G01 | B40: 39 | C40: Use Case - Correção de imagens | D40: Sprint 01 | E40: closed | F40: G01-A14 | G40: maintainer | H40: Integrante identificado | I40: ART.03;CODE;DOCUMENTATION;G | J40: CODE | K40: DOCUMENTATION | L40: ART.03; G | M40: rótulo de núcleo: CODE | N40: 2026-04-30 | O40: 2026-05-02
...
